Workbook

Sheet Raw Data
A1: EmpID | B1: EmployeeName | C1: Department | D1: Age | E1: JoiningDate | F1: ExitDate | G1: MonthlySalary | H1: PerformanceRating
A2: EMP0001 | B2: Kabir Sharma | C2: Operations | D2: 39 | E2: 2018-09-30 | F2: 2020-02-21 | G2: 45200 | H2: 5
A3: EMP0002 | B3: Reyansh Menon | C3: HR | D3: 24 | E3: 2016-05-02 | F3: 2019-03-10 | G3: 38100 | H3: 1
A4: EMP0003 | B4: Aadhya Pillai | C4: HR | D4: 36 | E4: 2021-01-13 | G4: 45400 | H4: 1
A5: EMP0004 | B5: Ananya Kapoor | C5: Finance | D5: 39 | E5: 2017-09-28 | F5: 2026-07-20 | G5: 49100 | H5: 2
A6: EMP0005 | B6: Ishaan Joshi | C6: Finance | D6: 38 | E6: 2025-01-18 | F6: 2025-12-09 | G6: 53900 | H6: 5
A7: EMP0006 | B7: Nikhil Gupta | C7: IT | D7: 40 | E7: 2025-04-20 | G7: 65300 | H7: 3
A8: EMP0007 | B8: Aadhya Gupta | C8: Sales | D8: 36 | E8: 2024-09-01 | G8: 29900 | H8: 3
A9: EMP0008 | B9: Ishaan Desai | C9: Finance | D9: 51 | E9: 2023-02-16 | G9: 44900 | H9: 3
A10: EMP0009 | B10: Anika Gupta | C10: IT | D10: 32 | E10: 2021-12-27 | G10: 47900 | H10: 3
A11: EMP0010 | B11: Meera Nair | C11: Operations | D11: 42 | E11: 2024-08-13 | G11: 34500 | H11: 1
A12: EMP0011 | B12: Rahul Desai | C12: Finance | D12: 26 | E12: 2018-05-14 | G12: 54600 | H12: 4
A13: EMP0012 | B13: Ira Chopra | C13: HR | D13: 51 | E13: 2017-08-08 | F13: 2020-08-12 | G13: 43900 | H13: 4
A14: EMP0013 | B14: Shreya Kapoor | C14: IT | D14: 47 | E14: 2020-01-22 | F14: 2021-11-08 | G14: 56200 | H14: 2
A15: EMP0014 | B15: Vihaan Kumar | C15: Marketing | D15: 32 | E15: 2024-11-18 | G15: 44300 | H15: 3
A16: EMP0015 | B16: Swati Malhotra | C16: IT | D16: 38 | E16: 2022-03-16 | G16: 44300 | H16: 4
A17: EMP0016 | B17: Sunita Iyer | C17: Operations | D17: 43 | E17: 2017-04-01 | G17: 32800 | H17: 1
A18: EMP0017 | B18: Kiara Bhat | C18: Marketing | D18: 54 | E18: 2017-03-11 | G18: 37200 | H18: 4
A19: EMP0018 | B19: Swati Reddy | C19: Marketing | D19: 45 | E19: 2024-07-20 | F19: 2026-04-14 | G19: 52000 | H19: 4
A20: EMP0019 | B20: Neha Sharma | C20: Sales | D20: 45 | E20: 2025-04-29 | G20: 33700 | H20: 3
A21: EMP0020 | B21: Divya Gupta | C21: Sales | D21: 53 | E21: 2025-02-24 | F21: 2026-06-18 | G21: 40800 | H21: 2
A22: EMP0021 | B22: Priya Pillai | C22: Marketing | D22: 38 | E22: 2021-12-01 | G22: 40200 | H22: 3
A23: EMP0022 | B23: Sunita Reddy | C23: Operations | D23: 41 | E23: 2020-06-22 | G23: 44600 | H23: 3
A24: EMP0023 | B24: Kavita Malhotra | C24: Sales | D24: 37 | E24: 2018-07-09 | F24: 2019-01-01 | G24: 42100 | H24: 3
A25: EMP0024 | B25: Myra Sharma | C25: Sales | D25: 25 | E25: 2018-07-26 | F25: 2019-03-01 | G25: 48600 | H25: 2
A26: EMP0025 | B26: Sara Iyer | C26: Operations | D26: 53 | E26: 2018-05-27 | G26: 46400 | H26: 5
A27: EMP0026 | B27: Divya Chopra | C27: Marketing | D27: 52 | E27: 2025-01-20 | G27: 32300 | H27: 4
A28: EMP0027 | B28: Sanjay Kapoor | C28: HR | D28: 51 | E28: 2024-03-05 | F28: 2026-04-03 | G28: 49600 | H28: 2
A29: EMP0028 | B29: Manoj Mehta | C29: Sales | D29: 37 | E29: 2018-02-23 | F29: 2023-06-04 | G29: 31400 | H29: 3
A30: EMP0029 | B30: Rajesh Nair | C30: Sales | D30: 50 | E30: 2025-01-22 | G30: 41200 | H30: 2
A31: EMP0030 | B31: Sunita Sharma | C31: Sales | D31: 37 | E31: 2017-11-12 | G31: 39600 | H31: 5
A32: EMP0031 | B32: Vihaan Patel | C32: HR | D32: 22 | E32: 2020-05-18 | F32: 2025-09-22 | G32: 32800 | H32: 4
A33: EMP0032 | B33: Meera Chopra | C33: Marketing | D33: 34 | E33: 2019-04-30 | F33: 2020-03-24 | G33: 43900 | H33: 4
A34: EMP0033 | B34: Rahul Verma | C34: Sales | D34: 52 | E34: 2021-08-21 | G34: 40700 | H34: 2
A35: EMP0034 | B35: Pooja Gupta | C35: Marketing | D35: 26 | E35: 2022-09-03 | F35: 2024-03-27 | G35: 39700 | H35: 5
A36: EMP0035 | B36: Divya Nair | C36: IT | D36: 24 | E36: 2022-12-11 | F36: 2026-06-18 | G36: 57600 | H36: 3
A37: EMP0036 | B37: Kiara Reddy | C37: Operations | D37: 42 | E37: 2018-09-04 | F37: 2020-05-22 | G37: 45100 | H37: 3
A38: EMP0037 | B38: Rahul Gupta | C38: Sales | D38: 51 | E38: 2022-12-19 | G38: 51900 | H38: 2
A39: EMP0038 | B39: Ira Bhat | C39: Finance | D39: 30 | E39: 2019-11-30 | G39: 62100 | H39: 3
A40: EMP0039 | B40: Ananya Malhotra | C40: IT | D40: 41 | E40: 2022-11-10 | G40: 63400 | H40: 4
...

Sheet Calculations
A1: EmpID | B1: EmployeeName | C1: Department | D1: Status | E1: TenureYears | F1: AgeBracket | G1: AnnualSalary | H1: SalaryBand | I1: SalaryRank | J1: EmpCode | K1: NextReviewDate | L1: RetentionRisk | M1: DeptLookupCheck
A2: ='Raw Data'!A2 -> EMP0001 | B2: =INDEX('Raw Data'!$B$2:$B$301, MATCH(A2,'Raw Data'!$A$2:$A$301,0)) -> Kabir Sharma | C2: =VLOOKUP($A2,'Raw Data'!$A$2:$C$301,3,FALSE) -> Operations | D2: =IF(ISBLANK('Raw Data'!F2),"Active","Resigned") -> Resigned | E2: =DATEDIF('Raw Data'!E2,IF(ISBLANK('Raw Data'!F2),TODAY(),'Raw Data'!F2),"Y") -> 1 | F2: =_xlfn.IFS('Raw Data'!D2<30,"Under 30",'Raw Data'!D2<=40,"30-40",'Raw Data'!D2<=50,"41-50",TRUE(),"51+") -> 30-40 | G2: ='Raw Data'!G2*12 -> 542400 | H2: =_xlfn.IFS(G2<420000,"Low",G2<540000,"Mid",G2<660000,"High",TRUE(),"Premium") -> High | I2: =RANK(G2,$G$2:$G$301) -> 149 | J2: =_xlfn.TEXTJOIN("-",TRUE(),LEFT(C2,3),A2) -> Ope-EMP0001 | K2: =EOMONTH('Raw Data'!E2,12*(YEAR(TODAY())-YEAR('Raw Data'!E2))+3) -> 46387 | L2: =IF(AND('Raw Data'!H2>=4,D2="Active",E2<2),"Watch","") | M2: =IFERROR(VLOOKUP($A2,'Raw Data'!$A$2:$C$50,3,FALSE()),"Not in first 49 rows") -> Operations
A3: ='Raw Data'!A3 -> EMP0002 | B3: =INDEX('Raw Data'!$B$2:$B$301, MATCH(A3,'Raw Data'!$A$2:$A$301,0)) -> Reyansh Menon | C3: =VLOOKUP($A3,'Raw Data'!$A$2:$C$301,3,FALSE) -> HR | D3: =IF(ISBLANK('Raw Data'!F3),"Active","Resigned") -> Resigned | E3: =DATEDIF('Raw Data'!E3,IF(ISBLANK('Raw Data'!F3),TODAY(),'Raw Data'!F3),"Y") -> 2 | F3: =_xlfn.IFS('Raw Data'!D3<30,"Under 30",'Raw Data'!D3<=40,"30-40",'Raw Data'!D3<=50,"41-50",TRUE(),"51+") -> Under 30 | G3: ='Raw Data'!G3*12 -> 457200 | H3: =_xlfn.IFS(G3<420000,"Low",G3<540000,"Mid",G3<660000,"High",TRUE(),"Premium") -> Mid | I3: =RANK(G3,$G$2:$G$301) -> 221 | J3: =_xlfn.TEXTJOIN("-",TRUE(),LEFT(C3,3),A3) -> HR-EMP0002 | K3: =EOMONTH('Raw Data'!E3,12*(YEAR(TODAY())-YEAR('Raw Data'!E3))+3) -> 46265 | L3: =IF(AND('Raw Data'!H3>=4,D3="Active",E3<2),"Watch","") | M3: =IFERROR(VLOOKUP($A3,'Raw Data'!$A$2:$C$50,3,FALSE()),"Not in first 49 rows") -> HR
A4: ='Raw Data'!A4 -> EMP0003 | B4: =INDEX('Raw Data'!$B$2:$B$301, MATCH(A4,'Raw Data'!$A$2:$A$301,0)) -> Aadhya Pillai | C4: =VLOOKUP($A4,'Raw Data'!$A$2:$C$301,3,FALSE) -> HR | D4: =IF(ISBLANK('Raw Data'!F4),"Active","Resigned") -> Active | E4: =DATEDIF('Raw Data'!E4,IF(ISBLANK('Raw Data'!F4),TODAY(),'Raw Data'!F4),"Y") -> 5 | F4: =_xlfn.IFS('Raw Data'!D4<30,"Under 30",'Raw Data'!D4<=40,"30-40",'Raw Data'!D4<=50,"41-50",TRUE(),"51+") -> 30-40 | G4: ='Raw Data'!G4*12 -> 544800 | H4: =_xlfn.IFS(G4<420000,"Low",G4<540000,"Mid",G4<660000,"High",TRUE(),"Premium") -> High | I4: =RANK(G4,$G$2:$G$301) -> 142 | J4: =_xlfn.TEXTJOIN("-",TRUE(),LEFT(C4,3),A4) -> HR-EMP0003 | K4: =EOMONTH('Raw Data'!E4,12*(YEAR(TODAY())-YEAR('Raw Data'!E4))+3) -> 46142 | L4: =IF(AND('Raw Data'!H4>=4,D4="Active",E4<2),"Watch","") | M4: =IFERROR(VLOOKUP($A4,'Raw Data'!$A$2:$C$50,3,FALSE()),"Not in first 49 rows") -> HR
A5: ='Raw Data'!A5 -> EMP0004 | B5: =INDEX('Raw Data'!$B$2:$B$301, MATCH(A5,'Raw Data'!$A$2:$A$301,0)) -> Ananya Kapoor | C5: =VLOOKUP($A5,'Raw Data'!$A$2:$C$301,3,FALSE) -> Finance | D5: =IF(ISBLANK('Raw Data'!F5),"Active","Resigned") -> Resigned | E5: =DATEDIF('Raw Data'!E5,IF(ISBLANK('Raw Data'!F5),TODAY(),'Raw Data'!F5),"Y") -> 8 | F5: =_xlfn.IFS('Raw Data'!D5<30,"Under 30",'Raw Data'!D5<=40,"30-40",'Raw Data'!D5<=50,"41-50",TRUE(),"51+") -> 30-40 | G5: ='Raw Data'!G5*12 -> 589200 | H5: =_xlfn.IFS(G5<420000,"Low",G5<540000,"Mid",G5<660000,"High",TRUE(),"Premium") -> High | I5: =RANK(G5,$G$2:$G$301) -> 107 | J5: =_xlfn.TEXTJOIN("-",TRUE(),LEFT(C5,3),A5) -> Fin-EMP0004 | K5: =EOMONTH('Raw Data'!E5,12*(YEAR(TODAY())-YEAR('Raw Data'!E5))+3) -> 46387 | L5: =IF(AND('Raw Data'!H5>=4,D5="Active",E5<2),"Watch","") | M5: =IFERROR(VLOOKUP($A5,'Raw Data'!$A$2:$C$50,3,FALSE()),"Not in first 49 rows") -> Finance
A6: ='Raw Data'!A6 -> EMP0005 | B6: =INDEX('Raw Data'!$B$2:$B$301, MATCH(A6,'Raw Data'!$A$2:$A$301,0)) -> Ishaan Joshi | C6: =VLOOKUP($A6,'Raw Data'!$A$2:$C$301,3,FALSE) -> Finance | D6: =IF(ISBLANK('Raw Data'!F6),"Active","Resigned") -> Resigned | E6: =DATEDIF('Raw Data'!E6,IF(ISBLANK('Raw Data'!F6),TODAY(),'Raw Data'!F6),"Y") -> 0 | F6: =_xlfn.IFS('Raw Data'!D6<30,"Under 30",'Raw Data'!D6<=40,"30-40",'Raw Data'!D6<=50,"41-50",TRUE(),"51+") -> 30-40 | G6: ='Raw Data'!G6*12 -> 646800 | H6: =_xlfn.IFS(G6<420000,"Low",G6<540000,"Mid",G6<660000,"High",TRUE(),"Premium") -> High | I6: =RANK(G6,$G$2:$G$301) -> 49 | J6: =_xlfn.TEXTJOIN("-",TRUE(),LEFT(C6,3),A6) -> Fin-EMP0005 | K6: =EOMONTH('Raw Data'!E6,12*(YEAR(TODAY())-YEAR('Raw Data'!E6))+3) -> 46142 | L6: =IF(AND('Raw Data'!H6>=4,D6="Active",E6<2),"Watch","") | M6: =IFERROR(VLOOKUP($A6,'Raw Data'!$A$2:$C$50,3,FALSE()),"Not in first 49 rows") -> Finance
A7: ='Raw Data'!A7 -> EMP0006 | B7: =INDEX('Raw Data'!$B$2:$B$301, MATCH(A7,'Raw Data'!$A$2:$A$301,0)) -> Nikhil Gupta | C7: =VLOOKUP($A7,'Raw Data'!$A$2:$C$301,3,FALSE) -> IT | D7: =IF(ISBLANK('Raw Data'!F7),"Active","Resigned") -> Active | E7: =DATEDIF('Raw Data'!E7,IF(ISBLANK('Raw Data'!F7),TODAY(),'Raw Data'!F7),"Y") -> 1 | F7: =_xlfn.IFS('Raw Data'!D7<30,"Under 30",'Raw Data'!D7<=40,"30-40",'Raw Data'!D7<=50,"41-50",TRUE(),"51+") -> 30-40 | G7: ='Raw Data'!G7*12 -> 783600 | H7: =_xlfn.IFS(G7<420000,"Low",G7<540000,"Mid",G7<660000,"High",TRUE(),"Premium") -> Premium | I7: =RANK(G7,$G$2:$G$301) -> 4 | J7: =_xlfn.TEXTJOIN("-",TRUE(),LEFT(C7,3),A7) -> IT-EMP0006 | K7: =EOMONTH('Raw Data'!E7,12*(YEAR(TODAY())-YEAR('Raw Data'!E7))+3) -> 46234 | L7: =IF(AND('Raw Data'!H7>=4,D7="Active",E7<2),"Watch","") | M7: =IFERROR(VLOOKUP($A7,'Raw Data'!$A$2:$C$50,3,FALSE()),"Not in first 49 rows") -> IT
A8: ='Raw Data'!A8 -> EMP0007 | B8: =INDEX('Raw Data'!$B$2:$B$301, MATCH(A8,'Raw Data'!$A$2:$A$301,0)) -> Aadhya Gupta | C8: =VLOOKUP($A8,'Raw Data'!$A$2:$C$301,3,FALSE) -> Sales | D8: =IF(ISBLANK('Raw Data'!F8),"Active","Resigned") -> Active | E8: =DATEDIF('Raw Data'!E8,IF(ISBLANK('Raw Data'!F8),TODAY(),'Raw Data'!F8),"Y") -> 1 | F8: =_xlfn.IFS('Raw Data'!D8<30,"Under 30",'Raw Data'!D8<=40,"30-40",'Raw Data'!D8<=50,"41-50",TRUE(),"51+") -> 30-40 | G8: ='Raw Data'!G8*12 -> 358800 | H8: =_xlfn.IFS(G8<420000,"Low",G8<540000,"Mid",G8<660000,"High",TRUE(),"Premium") -> Low | I8: =RANK(G8,$G$2:$G$301) -> 289 | J8: =_xlfn.TEXTJOIN("-",TRUE(),LEFT(C8,3),A8) -> Sal-EMP0007 | K8: =EOMONTH('Raw Data'!E8,12*(YEAR(TODAY())-YEAR('Raw Data'!E8))+3) -> 46387 | L8: =IF(AND('Raw Data'!H8>=4,D8="Active",E8<2),"Watch","") | M8: =IFERROR(VLOOKUP($A8,'Raw Data'!$A$2:$C$50,3,FALSE()),"Not in first 49 rows") -> Sales
A9: ='Raw Data'!A9 -> EMP0008 | B9: =INDEX('Raw Data'!$B$2:$B$301, MATCH(A9,'Raw Data'!$A$2:$A$301,0)) -> Ishaan Desai | C9: =VLOOKUP($A9,'Raw Data'!$A$2:$C$301,3,FALSE) -> Finance | D9: =IF(ISBLANK('Raw Data'!F9),"Active","Resigned") -> Active | E9: =DATEDIF('Raw Data'!E9,IF(ISBLANK('Raw Data'!F9),TODAY(),'Raw Data'!F9),"Y") -> 3 | F9: =_xlfn.IFS('Raw Data'!D9<30,"Under 30",'Raw Data'!D9<=40,"30-40",'Raw Data'!D9<=50,"41-50",TRUE(),"51+") -> 51+ | G9: ='Raw Data'!G9*12 -> 538800 | H9: =_xlfn.IFS(G9<420000,"Low",G9<540000,"Mid",G9<660000,"High",TRUE(),"Premium") -> Mid | I9: =RANK(G9,$G$2:$G$301) -> 154 | J9: =_xlfn.TEXTJOIN("-",TRUE(),LEFT(C9,3),A9) -> Fin-EMP0008 | K9: =EOMONTH('Raw Data'!E9,12*(YEAR(TODAY())-YEAR('Raw Data'!E9))+3) -> 46173 | L9: =IF(AND('Raw Data'!H9>=4,D9="Active",E9<2),"Watch","") | M9: =IFERROR(VLOOKUP($A9,'Raw Data'!$A$2:$C$50,3,FALSE()),"Not in first 49 rows") -> Finance
A10: ='Raw Data'!A10 -> EMP0009 | B10: =INDEX('Raw Data'!$B$2:$B$301, MATCH(A10,'Raw Data'!$A$2:$A$301,0)) -> Anika Gupta | C10: =VLOOKUP($A10,'Raw Data'!$A$2:$C$301,3,FALSE) -> IT | D10: =IF(ISBLANK('Raw Data'!F10),"Active","Resigned") -> Active | E10: =DATEDIF('Raw Data'!E10,IF(ISBLANK('Raw Data'!F10),TODAY(),'Raw Data'!F10),"Y") -> 4 | F10: =_xlfn.IFS('Raw Data'!D10<30,"Under 30",'Raw Data'!D10<=40,"30-40",'Raw Data'!D10<=50,"41-50",TRUE(),"51+") -> 30-40 | G10: ='Raw Data'!G10*12 -> 574800 | H10: =_xlfn.IFS(G10<420000,"Low",G10<540000,"Mid",G10<660000,"High",TRUE(),"Premium") -> High | I10: =RANK(G10,$G$2:$G$301) -> 114 | J10: =_xlfn.TEXTJOIN("-",TRUE(),LEFT(C10,3),A10) -> IT-EMP0009 | K10: =EOMONTH('Raw Data'!E10,12*(YEAR(TODAY())-YEAR('Raw Data'!E10))+3) -> 46477 | L10: =IF(AND('Raw Data'!H10>=4,D10="Active",E10<2),"Watch","") | M10: =IFERROR(VLOOKUP($A10,'Raw Data'!$A$2:$C$50,3,FALSE()),"Not in first 49 rows") -> IT
A11: ='Raw Data'!A11 -> EMP0010 | B11: =INDEX('Raw Data'!$B$2:$B$301, MATCH(A11,'Raw Data'!$A$2:$A$301,0)) -> Meera Nair | C11: =VLOOKUP($A11,'Raw Data'!$A$2:$C$301,3,FALSE) -> Operations | D11: =IF(ISBLANK('Raw Data'!F11),"Active","Resigned") -> Active | E11: =DATEDIF('Raw Data'!E11,IF(ISBLANK('Raw Data'!F11),TODAY(),'Raw Data'!F11),"Y") -> 1 | F11: =_xlfn.IFS('Raw Data'!D11<30,"Under 30",'Raw Data'!D11<=40,"30-40",'Raw Data'!D11<=50,"41-50",TRUE(),"51+") -> 41-50 | G11: ='Raw Data'!G11*12 -> 414000 | H11: =_xlfn.IFS(G11<420000,"Low",G11<540000,"Mid",G11<660000,"High",TRUE(),"Premium") -> Low | I11: =RANK(G11,$G$2:$G$301) -> 257 | J11: =_xlfn.TEXTJOIN("-",TRUE(),LEFT(C11,3),A11) -> Ope-EMP0010 | K11: =EOMONTH('Raw Data'!E11,12*(YEAR(TODAY())-YEAR('Raw Data'!E11))+3) -> 46356 | L11: =IF(AND('Raw Data'!H11>=4,D11="Active",E11<2),"Watch","") | M11: =IFERROR(VLOOKUP($A11,'Raw Data'!$A$2:$C$50,3,FALSE()),"Not in first 49 rows") -> Operations
A12: ='Raw Data'!A12 -> EMP0011 | B12: =INDEX('Raw Data'!$B$2:$B$301, MATCH(A12,'Raw Data'!$A$2:$A$301,0)) -> Rahul Desai | C12: =VLOOKUP($A12,'Raw Data'!$A$2:$C$301,3,FALSE) -> Finance | D12: =IF(ISBLANK('Raw Data'!F12),"Active","Resigned") -> Active | E12: =DATEDIF('Raw Data'!E12,IF(ISBLANK('Raw Data'!F12),TODAY(),'Raw Data'!F12),"Y") -> 8 | F12: =_xlfn.IFS('Raw Data'!D12<30,"Under 30",'Raw Data'!D12<=40,"30-40",'Raw Data'!D12<=50,"41-50",TRUE(),"51+") -> Under 30 | G12: ='Raw Data'!G12*12 -> 655200 | H12: =_xlfn.IFS(G12<420000,"Low",G12<540000,"Mid",G12<660000,"High",TRUE(),"Premium") -> High | I12: =RANK(G12,$G$2:$G$301) -> 45 | J12: =_xlfn.TEXTJOIN("-",TRUE(),LEFT(C12,3),A12) -> Fin-EMP0011 | K12: =EOMONTH('Raw Data'!E12,12*(YEAR(TODAY())-YEAR('Raw Data'!E12))+3) -> 46265 | L12: =IF(AND('Raw Data'!H12>=4,D12="Active",E12<2),"Watch","") | M12: =IFERROR(VLOOKUP($A12,'Raw Data'!$A$2:$C$50,3,FALSE()),"Not in first 49 rows") -> Finance
A13: ='Raw Data'!A13 -> EMP0012 | B13: =INDEX('Raw Data'!$B$2:$B$301, MATCH(A13,'Raw Data'!$A$2:$A$301,0)) -> Ira Chopra | C13: =VLOOKUP($A13,'Raw Data'!$A$2:$C$301,3,FALSE) -> HR | D13: =IF(ISBLANK('Raw Data'!F13),"Active","Resigned") -> Resigned | E13: =DATEDIF('Raw Data'!E13,IF(ISBLANK('Raw Data'!F13),TODAY(),'Raw Data'!F13),"Y") -> 3 | F13: =_xlfn.IFS('Raw Data'!D13<30,"Under 30",'Raw Data'!D13<=40,"30-40",'Raw Data'!D13<=50,"41-50",TRUE(),"51+") -> 51+ | G13: ='Raw Data'!G13*12 -> 526800 | H13: =_xlfn.IFS(G13<420000,"Low",G13<540000,"Mid",G13<660000,"High",TRUE(),"Premium") -> Mid | I13: =RANK(G13,$G$2:$G$301) -> 167 | J13: =_xlfn.TEXTJOIN("-",TRUE(),LEFT(C13,3),A13) -> HR-EMP0012 | K13: =EOMONTH('Raw Data'!E13,12*(YEAR(TODAY())-YEAR('Raw Data'!E13))+3) -> 46356 | L13: =IF(AND('Raw Data'!H13>=4,D13="Active",E13<2),"Watch","") | M13: =IFERROR(VLOOKUP($A13,'Raw Data'!$A$2:$C$50,3,FALSE()),"Not in first 49 rows") -> HR
... A301: ='Raw Data'!A301 -> EMP0300 | B301: =INDEX('Raw Data'!$B$2:$B$301, MATCH(A301,'Raw Data'!$A$2:$A$301,0)) -> Amit Nair | C301: =VLOOKUP($A301,'Raw Data'!$A$2:$C$301,3,FALSE) -> HR | D301: =IF(ISBLANK('Raw Data'!F301),"Active","Resigned") -> Resigned | E301: =DATEDIF('Raw Data'!E301,IF(ISBLANK('Raw Data'!F301),TODAY(),'Raw Data'!F301),"Y") -> 1 | F301: =_xlfn.IFS('Raw Data'!D301<30,"Under 30",'Raw Data'!D301<=40,"30-40",'Raw Data'!D301<=50,"41-50",TRUE(),"51+") -> 51+ | G301: ='Raw Data'!G301*12 -> 500400 | H301: =_xlfn.IFS(G301<420000,"Low",G301<540000,"Mid",G301<660000,"High",TRUE(),"Premium") -> Mid | I301: =RANK(G301,$G$2:$G$301) -> 188 | J301: =_xlfn.TEXTJOIN("-",TRUE(),LEFT(C301,3),A301) -> HR-EMP0300 | K301: =EOMONTH('Raw Data'!E301,12*(YEAR(TODAY())-YEAR('Raw Data'!E301))+3) -> 46265 | L301: =IF(AND('Raw Data'!H301>=4,D301="Active",E301<2),"Watch","") | M301: =IFERROR(VLOOKUP($A301,'Raw Data'!$A$2:$C$50,3,FALSE()),"Not in first 49 rows") -> Not in first 49 rows

Sheet Analysis
A1: Department-wise HR Analysis
A3: Department | B3: Headcount | C3: Active | D3: Resigned | E3: AttritionRate | F3: AvgSalary(Annual) | G3: AvgTenure(Yrs) | H3: AvgPerformance
A4: Sales | B4: =COUNTIFS(Calculations!$C$2:$C$301,A4) -> 57 | C4: =COUNTIFS(Calculations!$C$2:$C$301,A4,Calculations!$D$2:$D$301,"Active") -> 40 | D4: =COUNTIFS(Calculations!$C$2:$C$301,A4,Calculations!$D$2:$D$301,"Resigned") -> 17 | E4: =IFERROR(D4/B4,0) -> 0.29824561 | F4: =AVERAGEIFS(Calculations!$G$2:$G$301,Calculations!$C$2:$C$301,A4) -> 480000 | G4: =AVERAGEIFS(Calculations!$E$2:$E$301,Calculations!$C$2:$C$301,A4) -> 4.2631579 | H4: =AVERAGEIFS('Raw Data'!$H$2:$H$301,'Raw Data'!$C$2:$C$301,A4) -> 3.1052632
A5: Marketing | B5: =COUNTIFS(Calculations!$C$2:$C$301,A5) -> 51 | C5: =COUNTIFS(Calculations!$C$2:$C$301,A5,Calculations!$D$2:$D$301,"Active") -> 40 | D5: =COUNTIFS(Calculations!$C$2:$C$301,A5,Calculations!$D$2:$D$301,"Resigned") -> 11 | E5: =IFERROR(D5/B5,0) -> 0.21568627 | F5: =AVERAGEIFS(Calculations!$G$2:$G$301,Calculations!$C$2:$C$301,A5) -> 515623.53 | G5: =AVERAGEIFS(Calculations!$E$2:$E$301,Calculations!$C$2:$C$301,A5) -> 4.4509804 | H5: =AVERAGEIFS('Raw Data'!$H$2:$H$301,'Raw Data'!$C$2:$C$301,A5) -> 3.4705882
A6: Finance | B6: =COUNTIFS(Calculations!$C$2:$C$301,A6) -> 42 | C6: =COUNTIFS(Calculations!$C$2:$C$301,A6,Calculations!$D$2:$D$301,"Active") -> 28 | D6: =COUNTIFS(Calculations!$C$2:$C$301,A6,Calculations!$D$2:$D$301,"Resigned") -> 14 | E6: =IFERROR(D6/B6,0) -> 0.33333333 | F6: =AVERAGEIFS(Calculations!$G$2:$G$301,Calculations!$C$2:$C$301,A6) -> 623000 | G6: =AVERAGEIFS(Calculations!$E$2:$E$301,Calculations!$C$2:$C$301,A6) -> 4.0952381 | H6: =AVERAGEIFS('Raw Data'!$H$2:$H$301,'Raw Data'!$C$2:$C$301,A6) -> 3.5
A7: HR | B7: =COUNTIFS(Calculations!$C$2:$C$301,A7) -> 48 | C7: =COUNTIFS(Calculations!$C$2:$C$301,A7,Calculations!$D$2:$D$301,"Active") -> 34 | D7: =COUNTIFS(Calculations!$C$2:$C$301,A7,Calculations!$D$2:$D$301,"Resigned") -> 14 | E7: =IFERROR(D7/B7,0) -> 0.29166667 | F7: =AVERAGEIFS(Calculations!$G$2:$G$301,Calculations!$C$2:$C$301,A7) -> 457125 | G7: =AVERAGEIFS(Calculations!$E$2:$E$301,Calculations!$C$2:$C$301,A7) -> 4.625 | H7: =AVERAGEIFS('Raw Data'!$H$2:$H$301,'Raw Data'!$C$2:$C$301,A7) -> 3.5
A8: IT | B8: =COUNTIFS(Calculations!$C$2:$C$301,A8) -> 50 | C8: =COUNTIFS(Calculations!$C$2:$C$301,A8,Calculations!$D$2:$D$301,"Active") -> 38 | D8: =COUNTIFS(Calculations!$C$2:$C$301,A8,Calculations!$D$2:$D$301,"Resigned") -> 12 | E8: =IFERROR(D8/B8,0) -> 0.24 | F8: =AVERAGEIFS(Calculations!$G$2:$G$301,Calculations!$C$2:$C$301,A8) -> 680472 | G8: =AVERAGEIFS(Calculations!$E$2:$E$301,Calculations!$C$2:$C$301,A8) -> 4.98 | H8: =AVERAGEIFS('Raw Data'!$H$2:$H$301,'Raw Data'!$C$2:$C$301,A8) -> 3.38
A9: Operations | B9: =COUNTIFS(Calculations!$C$2:$C$301,A9) -> 52 | C9: =COUNTIFS(Calculations!$C$2:$C$301,A9,Calculations!$D$2:$D$301,"Active") -> 33 | D9: =COUNTIFS(Calculations!$C$2:$C$301,A9,Calculations!$D$2:$D$301,"Resigned") -> 19 | E9: =IFERROR(D9/B9,0) -> 0.36538462 | F9: =AVERAGEIFS(Calculations!$G$2:$G$301,Calculations!$C$2:$C$301,A9) -> 512030.77 | G9: =AVERAGEIFS(Calculations!$E$2:$E$301,Calculations!$C$2:$C$301,A9) -> 4.5769231 | H9: =AVERAGEIFS('Raw Data'!$H$2:$H$301,'Raw Data'!$C$2:$C$301,A9) -> 3.0576923
A10: TOTAL / OVERALL | B10: =SUM(B4:B9) -> 300 | C10: =SUM(C4:C9) -> 213 | D10: =SUM(D4:D9) -> 87 | E10: =IFERROR(D10/B10,0) -> 0.29 | F10: =AVERAGE(Calculations!$G$2:$G$301) -> 541380 | G10: =AVERAGE(Calculations!$E$2:$E$301) -> 4.5033333 | H10: =AVERAGE('Raw Data'!$H$2:$H$301) -> 3.3233333
A12: Overall Salary Statistics
A13: Median Annual Salary | B13: =MEDIAN(Calculations!$G$2:$G$301) -> 541200
A14: Std Dev Annual Salary | B14: =STDEV(Calculations!$G$2:$G$301) -> 112948.87
A15: 90th Percentile Salary | B15: =PERCENTILE(Calculations!$G$2:$G$301,0.9) -> 697320
A16: Max Annual Salary | B16: =MAX(Calculations!$G$2:$G$301) -> 814800
A17: Min Annual Salary | B17: =MIN(Calculations!$G$2:$G$301) -> 316800
A18: High Performers (Rating>=4) | B18: =COUNTIFS('Raw Data'!$H$2:$H$301,">=4") -> 131
A19: Total Salary Cost (SUMPRODUCT check) | B19: {=SUMPRODUCT((Calculations!$D$2:$D$301="Active")*Calculations!$G$2:$G$301)} -> 115310400

Sheet Dashboard
A1: EMPLOYEE ATTRITION & HR ANALYTICS DASHBOARD
B3: Total Headcount | E3: Overall Attrition Rate | H3: Avg Annual Salary | K3: Avg Tenure (Yrs)
B4: =Analysis!B10 -> 300 | E4: =Analysis!E10 -> 0.29 | H4: =Analysis!F10 -> 541380 | K4: =Analysis!G10 -> 4.5033333
B9: Department | C9: Sum Headcount | D9: Attrition Rate
B10: Finance | C10: 42 | D10: 0.33333333
B11: HR | C11: 48 | D11: 0.29166667
B12: IT | C12: 50 | D12: 0.24
B13: Marketing | C13: 51 | D13: 0.21568627
B14: Operations | C14: 52 | D14: 0.36538462
B15: Sales | C15: 57 | D15: 0.29824561
B16: Grand Total | C16: 300 | D16: 1.7443165

Sheet Formula Reference
A1: Formula Reference Guide
A3: Category | B3: Formula | C3: Example Location | D3: Purpose
A4: Lookup | B4: VLOOKUP | C4: Calculations!C2 | D4: Pull Department for an EmpID from Raw Data
A5: Lookup | B5: INDEX + MATCH | C5: Calculations!B2 | D5: Pull EmployeeName for an EmpID (2-way flexible lookup)
A6: Logical | B6: IF | C6: Calculations!D2 | D6: Classify employee as Active or Resigned
A7: Logical | B7: IFS | C7: Calculations!F2, H2 | D7: Multi-condition bucketing (Age Bracket, Salary Band)
A8: Logical | B8: AND | C8: Calculations!L2 | D8: Flag Retention Risk when 3 conditions are all true
A9: Error handling | B9: IFERROR | C9: Calculations!M2, Analysis!E4 | D9: Return a fallback instead of a lookup or divide-by-zero error
A10: Conditional aggregation | B10: COUNTIFS | C10: Analysis!B4:D9 | D10: Headcount, Active, Resigned counts per department
A11: Conditional aggregation | B11: AVERAGEIFS | C11: Analysis!F4:H9 | D11: Avg salary, tenure, performance per department
A12: Text | B12: LEFT | C12: Calculations!J2 | D12: First 3 letters of Department for EmpCode
A13: Text | B13: TEXTJOIN | C13: Calculations!J2 | D13: Join department code and EmpID with a delimiter
A14: Date | B14: DATEDIF | C14: Calculations!E2 | D14: Tenure in completed years
... A22: Visualization | B22: Bar Chart / Pie Chart | C22: Dashboard | D22: Headcount and attrition visuals
A25: Note: XLOOKUP, FILTER, SORT and UNIQUE are newer dynamic-array functions. This workbook uses VLOOKUP/INDEX-MATCH instead so every formula recalculates reliably across Excel versions. Try rebuilding the lookups with XLOOKUP yourself once you're comfortable with these basics.
